<?xml version="1.0" ?>
<robot name="bbot" xmlns:xacro="http://www.ros.org/wiki/xacro">


<xacro:include filename="$(find bbot_description)/urdf/camera.xacro" />
<xacro:include filename="$(find bbot_description)/urdf/lidar.xacro" />
<xacro:include filename="$(find bbot_description)/urdf/diff_drive.xacro" />
<!-- <xacro:include filename="$(find bbot_description)/urdf/ros2_control.xacro" /> -->


<material name="silver">
  <color rgba="0.700 0.700 0.700 1.000"/>
</material>

<link name="base_footprint" />

<link name="base_link">
  <inertial>
    <origin xyz="-0.006057605134441126 -0.00018111500705384267 0.10888749093150545" rpy="0 0 0"/>
    <mass value="1.049122069689706"/>
    <inertia ixx="0.006186" iyy="0.006006" izz="0.00631" ixy="-0.0" iyz="0.0" ixz="-0.000632"/>
  </inertial>
  <visual>
    <origin xyz="0 0 0" rpy="0 0 0"/>
    <geometry>
      <mesh filename="file://$(find bbot_description)/meshes/base_link.stl" scale="0.001 0.001 0.001"/>
    </geometry>
    <material name="silver"/>
  </visual>
  <collision>
    <origin xyz="0 0 0" rpy="0 0 0"/>
    <geometry>
      <mesh filename="file://$(find bbot_description)/meshes/base_link.stl" scale="0.001 0.001 0.001"/>
    </geometry>
  </collision>
</link>

<gazebo reference="base_link">
  <material>Gazebo/Silver</material>
  <mu1>0.2</mu1>
  <mu2>0.2</mu2>
  <self_collide>true</self_collide>
  <gravity>true</gravity>
</gazebo>

<link name="lidar">
  <inertial>
    <origin xyz="-3.6197078243972464e-07 -1.1500705524792785e-07 0.007500311251273456" rpy="0 0 0"/>
    <mass value="0.02686061718819272"/>
    <inertia ixx="3e-06" iyy="3e-06" izz="5e-06" ixy="-0.0" iyz="0.0" ixz="0.0"/>
  </inertial>
  <visual>
    <origin xyz="-0.000257 0.000181 -0.193407" rpy="0 0 0"/>
    <geometry>
      <mesh filename="file://$(find bbot_description)/meshes/lidar_1.stl" scale="0.001 0.001 0.001"/>
    </geometry>
    <material name="silver"/>
  </visual>
  <collision>
    <origin xyz="-0.000257 0.000181 -0.193407" rpy="0 0 0"/>
    <geometry>
      <mesh filename="file://$(find bbot_description)/meshes/lidar_1.stl" scale="0.001 0.001 0.001"/>
    </geometry>
  </collision>
</link>

<gazebo reference="lidar">
  <material>Gazebo/Black</material>
  <mu1>0.2</mu1>
  <mu2>0.2</mu2>
  <self_collide>true</self_collide>
</gazebo>

<link name="camera">
  <inertial>
    <origin xyz="0.0009996380292177226 -1.150070553431208e-07 3.138589770024236e-07" rpy="0 0 0"/>
    <mass value="0.0017100000509619655"/>
    <inertia ixx="0.0" iyy="0.0" izz="0.0" ixy="-0.0" iyz="0.0" ixz="0.0"/>
  </inertial>
  <visual>
    <origin xyz="-0.102757 0.000181 -0.175407" rpy="0 0 0"/>
    <geometry>
      <mesh filename="file://$(find bbot_description)/meshes/camera_1.stl" scale="0.001 0.001 0.001"/>
    </geometry>
    <material name="silver"/>
  </visual>
  <collision>
    <origin xyz="-0.102757 0.000181 -0.175407" rpy="0 0 0"/>
    <geometry>
      <mesh filename="file://$(find bbot_description)/meshes/camera_1.stl" scale="0.001 0.001 0.001"/>
    </geometry>
  </collision>
</link>

<gazebo reference="camera">
  <material>Gazebo/Red</material>
  <mu1>0.2</mu1>
  <mu2>0.2</mu2>
  <self_collide>true</self_collide>
</gazebo>

<link name="camera_optical_link"/>

<link name="rightwheel">
  <inertial>
    <origin xyz="-3.6279034571623514e-07 -0.012500115007057472 3.1181752010306374e-07" rpy="0 0 0"/>
    <mass value="0.11821469543761899"/>
    <inertia ixx="3.7e-05" iyy="6.2e-05" izz="3.7e-05" ixy="-0.0" iyz="0.0" ixz="-0.0"/>
  </inertial>
  <visual>
    <origin xyz="0.054743 0.112681 -0.038407" rpy="0 0 0"/>
    <geometry>
      <mesh filename="file://$(find bbot_description)/meshes/rightwheel_1.stl" scale="0.001 0.001 0.001"/>
    </geometry>
    <material name="silver"/>
  </visual>
  <collision>
    <origin xyz="0.054743 0.112681 -0.038407" rpy="0 0 0"/>
    <geometry>
      <mesh filename="file://$(find bbot_description)/meshes/rightwheel_1.stl" scale="0.001 0.001 0.001"/>
    </geometry>
  </collision>
</link>

<gazebo reference="rightwheel">
  <material>Gazebo/Black</material>
  <mu1>1</mu1>
  <mu2>1</mu2>
  <self_collide>true</self_collide>
</gazebo>

<link name="leftwheel">
  <inertial>
    <origin xyz="-3.627903472150362e-07 0.012499884992944452 3.118175187846739e-07" rpy="0 0 0"/>
    <mass value="0.11821469543761903"/>
    <inertia ixx="3.7e-05" iyy="6.2e-05" izz="3.7e-05" ixy="-0.0" iyz="-0.0" ixz="0.0"/>
  </inertial>
  <visual>
    <origin xyz="0.054743 -0.112319 -0.038407" rpy="0 0 0"/>
    <geometry>
      <mesh filename="file://$(find bbot_description)/meshes/leftwheel_1.stl" scale="0.001 0.001 0.001"/>
    </geometry>
    <material name="silver"/>
  </visual>
  <collision>
    <origin xyz="0.054743 -0.112319 -0.038407" rpy="0 0 0"/>
    <geometry>
      <mesh filename="file://$(find bbot_description)/meshes/leftwheel_1.stl" scale="0.001 0.001 0.001"/>
    </geometry>
  </collision>
</link>

<gazebo reference="leftwheel">
  <material>Gazebo/Black</material>
  <mu1>1</mu1>
  <mu2>1</mu2>
  <self_collide>true</self_collide>
</gazebo>




<joint name="base_basefootprint_joint" type="fixed">
  <origin xyz="0 0 0" rpy="0 0 0"/>
  <parent link="base_link"/>
  <child link="base_footprint"/>
</joint>

<joint name="base_lidar_joint" type="fixed">
  <origin xyz="0.000257 -0.000181 0.194407" rpy="0 0 0"/>
  <parent link="base_link"/>
  <child link="lidar"/>
</joint>

<joint name="base_camera_joint" type="fixed">
  <origin xyz="0.102757 -0.000181 0.175407" rpy="0 0 0"/>
  <parent link="base_link"/>
  <child link="camera"/>
</joint>

<joint name="camera_cameraoptical_joint" type="fixed">
  <parent link="camera"/>
  <child link="camera_optical_link"/>
  <origin xyz="0 0 0" rpy="${-pi/2} 0 ${-pi/2}" />
</joint>

<joint name="base_rightwheel_joint" type="continuous">
  <origin xyz="-0.054743 -0.112681 0.038407" rpy="0 0 0"/>
  <parent link="base_link"/>
  <child link="rightwheel"/>
  <axis xyz="0 1 0"/>
</joint>

<joint name="base_leftwheel_joint" type="continuous">
  <origin xyz="-0.054743 0.112319 0.038407" rpy="0 0 0"/>
  <parent link="base_link"/>
  <child link="leftwheel"/>
  <axis xyz="0 1 0"/>
</joint>

</robot>
